ENSG00000125826.csv ENSG00000125826 rs566912235 gnomadgenomesr3.0_ENSG00000125826_rs566912235.csv   gnomADg:eas A: 1.000 (3130) G: 0.000 
ENSG00000125826.csv ENSG00000125826 rs566912235 gnomadgenomesr3.0_ENSG00000125826_rs566912235.csv   gnomADg:fin A: 1.000 (10482) G: 0.000 
ENSG00000125826.csv ENSG00000125826 rs566912235 gnomadgenomesr3.0_ENSG00000125826_rs566912235.csv   gnomADg:nfe A: 1.000 (64570) G: 0.000 
ENSG00000125826.csv ENSG00000125826 rs566912235 gnomadgenomesr3.0_ENSG00000125826_rs566912235.csv   gnomADg:oth A: 1.000 (2152) G: 0.000 
ENSG00000125826.csv ENSG00000125826 rs566912235 gnomadgenomesr3.0_ENSG00000125826_rs566912235.csv   gnomADg:sas A: 1.000 (3048) G: 0.000 
Traceback (most recent call last):
  File "/home/bruno/Documents/dev/pibic_2020/venv-pibic-2020/lib/python3.8/site-packages/pandas/core/indexes/base.py", line 3080, in get_loc
    return self._engine.get_loc(casted_key)
  File "pandas/_libs/index.pyx", line 70, in pandas._libs.index.IndexEngine.get_loc
  File "pandas/_libs/index.pyx", line 101, in pandas._libs.index.IndexEngine.get_loc
  File "pandas/_libs/hashtable_class_helper.pxi", line 4554, in pandas._libs.hashtable.PyObjectHashTable.get_item
  File "pandas/_libs/hashtable_class_helper.pxi", line 4562, in pandas._libs.hashtable.PyObjectHashTable.get_item
KeyError: 'Variant ID'

The above exception was the direct cause of the following exception:

Traceback (most recent call last):
  File "main.py", line 61, in <module>
    df['Variant ID']
  File "/home/bruno/Documents/dev/pibic_2020/venv-pibic-2020/lib/python3.8/site-packages/pandas/core/frame.py", line 3024, in __getitem__
    indexer = self.columns.get_loc(key)
  File "/home/bruno/Documents/dev/pibic_2020/venv-pibic-2020/lib/python3.8/site-packages/pandas/core/indexes/base.py", line 3082, in get_loc
    raise KeyError(key) from err
KeyError: 'Variant ID'